<?xml version="1.0" ?>
<!-- =================================================================================== -->
<!-- |    This document was autogenerated by xacro from raspigibbon.urdf.xacro         | -->
<!-- |    EDITING THIS FILE BY HAND IS NOT RECOMMENDED                                 | -->
<!-- =================================================================================== -->
<robot name="raspigibbon" xmlns:controller="http://playerstage.sourceforge.net/gazebo/xmlschema/#controller" xmlns:interface="http://playerstage.sourceforge.net/gazebo/xmlschema/#interface" xmlns:sensor="http://playerstage.sourceforge.net/gazebo/xmlschema/#sensor" xmlns:xacro="http://ros.org/wiki/xacro">
  <!-- ========== Link & Joint ========== -->
  <link name="world"/>
  <joint name="world2base" type="fixed">
    <parent link="world"/>
    <child link="base_link"/>
  </joint>
  <link name="base_link">
    <visual>
      <geometry>
        <mesh filename="package://raspigibbon_description/meshes/dae/base_link.dae"/>
      </geometry>
    </visual>
    <collision>
      <geometry>
        <mesh filename="package://raspigibbon_description/meshes/dae/base_link.dae"/>
      </geometry>
    </collision>
    <inertial>
      <origin xyz="0 -0.008722 0.01556 "/>
      <mass value="0.060272"/>
      <inertia ixx="0.000080586983" ixy="-0.000000000016" ixz="0" iyy="0.000042795591" iyz="0" izz="0.000123342393"/>
    </inertial>
  </link>
  <joint name="joint0" type="fixed">
    <origin xyz="0.0 0.0 0.0"/>
    <parent link="base_link"/>
    <child link="link0"/>
  </joint>
  <link name="link0">
    <visual>
      <geometry>
        <mesh filename="package://raspigibbon_description/meshes/dae/servo1_link.dae"/>
      </geometry>
    </visual>
    <collision>
      <geometry>
        <mesh filename="package://raspigibbon_description/meshes/dae/servo1_link.dae"/>
      </geometry>
    </collision>
    <inertial>
      <origin xyz="0 -0.008722 0.01556 "/>
      <mass value="0.022267"/>
      <inertia ixx="0.000003621474" ixy="0.000000000001" ixz="-0.000000000001" iyy="0.000001983132" iyz="-0.000000215045" izz="0.000003182899"/>
    </inertial>
  </link>
  <joint name="joint1" type="revolute">
    <origin rpy="0 0 0" xyz="0 0 0.029"/>
    <axis xyz="0 0 -1"/>
    <limit effort="0.5293" lower="-2.52" upper="2.52" velocity="6.159937255"/>
    <friction friction="1.0"/>
    <dynamics damping="1.0"/>
    <parent link="link0"/>
    <child link="link1"/>
  </joint>
  <link name="link1">
    <visual>
      <geometry>
        <mesh filename="package://raspigibbon_description/meshes/dae/servo2_link.dae"/>
      </geometry>
    </visual>
    <collision>
      <geometry>
        <mesh filename="package://raspigibbon_description/meshes/dae/servo2_link.dae"/>
      </geometry>
    </collision>
    <inertial>
      <origin xyz="0.000157 0 0.019222"/>
      <mass value="0.023032"/>
      <inertia ixx="0.000003514815" ixy="-0.000000000001" ixz="-0.000000004487" iyy="0.000003930066" iyz="0.000000000001" izz="0.000001852796"/>
    </inertial>
  </link>
  <joint name="joint2" type="revolute">
    <origin rpy="0 0 0" xyz="0 0 0.03055"/>
    <axis xyz="1 0 0"/>
    <limit effort="0.5293" lower="-2.52" upper="2.52" velocity="6.159937255"/>
    <friction friction="1.0"/>
    <dynamics damping="1.0"/>
    <parent link="link1"/>
    <child link="link2"/>
  </joint>
  <link name="link2">
    <visual>
      <geometry>
        <mesh filename="package://raspigibbon_description/meshes/dae/servo3_link.dae"/>
      </geometry>
    </visual>
    <collision>
      <geometry>
        <mesh filename="package://raspigibbon_description/meshes/dae/servo3_link.dae"/>
      </geometry>
    </collision>
    <inertial>
      <origin xyz="0.000136 0 0.007403"/>
      <mass value="0.032345"/>
      <inertia ixx="0.000017682369" ixy="-0.000000000049" ixz="-0.000000000767" iyy="0.000019757486" iyz="0.000000000197" izz="0.000004109466"/>
    </inertial>
  </link>
  <joint name="joint3" type="revolute">
    <origin rpy="0 0 0" xyz="0 0 0.08055"/>
    <axis xyz="1 0 0"/>
    <limit effort="0.5293" lower="-2.52" upper="2.52" velocity="6.159937255"/>
    <friction friction="1.0"/>
    <dynamics damping="1.0"/>
    <parent link="link2"/>
    <child link="link3"/>
  </joint>
  <link name="link3">
    <visual>
      <geometry>
        <mesh filename="package://raspigibbon_description/meshes/dae/servo4_link.dae"/>
      </geometry>
    </visual>
    <collision>
      <geometry>
        <mesh filename="package://raspigibbon_description/meshes/dae/servo4_link.dae"/>
      </geometry>
    </collision>
    <inertial>
      <origin xyz="0.000136 0 0.007403"/>
      <mass value="0.032345"/>
      <inertia ixx="0.000017682369" ixy="-0.000000000049" ixz="-0.000000000767" iyy="0.000019757486" iyz="0.000000000197" izz="0.000004109466"/>
    </inertial>
  </link>
  <joint name="joint4" type="revolute">
    <origin rpy="0 0 0" xyz="0 0 0.08055"/>
    <axis xyz="1 0 0"/>
    <limit effort="0.5293" lower="-1.99" upper="1.99" velocity="6.159937255"/>
    <friction friction="1.0"/>
    <dynamics damping="1.0"/>
    <parent link="link3"/>
    <child link="link4"/>
  </joint>
  <link name="link4">
    <visual>
      <geometry>
        <mesh filename="package://raspigibbon_description/meshes/dae/servo5_link.dae"/>
      </geometry>
    </visual>
    <collision>
      <geometry>
        <mesh filename="package://raspigibbon_description/meshes/dae/servo5_link.dae"/>
      </geometry>
    </collision>
    <inertial>
      <origin xyz="0.000253 0.000821 0.013947"/>
      <mass value="0.041117"/>
      <inertia ixx="0.000006913101" ixy="0.000000054083" ixz="-0.000000059992" iyy="0.000009528465" iyz="-0.000000095617" izz="0.000008648857"/>
    </inertial>
  </link>
  <joint name="joint5" type="revolute">
    <origin rpy="0 -1.5708 -1.5708" xyz="-0.0091 0 0.0342"/>
    <axis xyz="0 0 1"/>
    <!-- <limit lower="&#45;1.57" upper="1.57" effort="0.5293" velocity="6.159937255" /> -->
    <limit effort="0.5293" lower="-1.92" upper="0.05" velocity="6.159937255"/>
    <friction friction="1.0"/>
    <dynamics damping="1.0"/>
    <parent link="link4"/>
    <child link="link5"/>
  </joint>
  <link name="link5">
    <visual>
      <geometry>
        <mesh filename="package://raspigibbon_description/meshes/dae/hand_link1.dae"/>
      </geometry>
    </visual>
    <collision>
      <geometry>
        <mesh filename="package://raspigibbon_description/meshes/dae/hand_link1.dae"/>
      </geometry>
    </collision>
    <inertial>
      <origin xyz="0.000253 0.000821 0.013947"/>
      <mass value="0.041117"/>
      <inertia ixx="0.000006913101" ixy="0.000000054083" ixz="-0.000000059992" iyy="0.000009528465" iyz="-0.000000095617" izz="0.000008648857"/>
    </inertial>
  </link>
  <joint name="joint6" type="revolute">
    <origin rpy="0 -1.5708 -1.5708" xyz="0.0091 0.0 0.0342"/>
    <axis xyz="0 0 1"/>
    <!-- <limit lower="&#45;1.57" upper="1.57" effort="0.5293" velocity="6.159937255" /> -->
    <limit effort="0.5293" lower="-0.05" upper="1.92" velocity="6.159937255"/>
    <friction friction="1.0"/>
    <dynamics damping="1.0"/>
    <parent link="link4"/>
    <child link="link6"/>
  </joint>
  <link name="link6">
    <visual>
      <geometry>
        <mesh filename="package://raspigibbon_description/meshes/dae/hand_link2.dae"/>
      </geometry>
    </visual>
    <collision>
      <geometry>
        <mesh filename="package://raspigibbon_description/meshes/dae/hand_link2.dae"/>
      </geometry>
    </collision>
    <inertial>
      <origin xyz="0.000253 0.000821 0.013947"/>
      <mass value="0.041117"/>
      <inertia ixx="0.000006913101" ixy="0.000000054083" ixz="-0.000000059992" iyy="0.000009528465" iyz="-0.000000095617" izz="0.000008648857"/>
    </inertial>
  </link>
  <!-- ========== Transmission ========== -->
  <transmission name="joint1_trans">
    <type>transmission_interface/SimpleTransmission</type>
    <joint name="joint1">
      <hardwareInterface>PositionJointInterface</hardwareInterface>
    </joint>
    <actuator name="joint1_motor">
      <hardwareInterface>PositionJointInterface</hardwareInterface>
      <mechanicalReduction>1</mechanicalReduction>
    </actuator>
  </transmission>
  <transmission name="joint2_trans">
    <type>transmission_interface/SimpleTransmission</type>
    <joint name="joint2">
      <hardwareInterface>PositionJointInterface</hardwareInterface>
    </joint>
    <actuator name="joint2_motor">
      <hardwareInterface>PositionJointInterface</hardwareInterface>
      <mechanicalReduction>1</mechanicalReduction>
    </actuator>
  </transmission>
  <transmission name="joint3_trans">
    <type>transmission_interface/SimpleTransmission</type>
    <joint name="joint3">
      <hardwareInterface>PositionJointInterface</hardwareInterface>
    </joint>
    <actuator name="joint3_motor">
      <hardwareInterface>PositionJointInterface</hardwareInterface>
      <mechanicalReduction>1</mechanicalReduction>
    </actuator>
  </transmission>
  <transmission name="joint4_trans">
    <type>transmission_interface/SimpleTransmission</type>
    <joint name="joint4">
      <hardwareInterface>PositionJointInterface</hardwareInterface>
    </joint>
    <actuator name="joint4_motor">
      <hardwareInterface>PositionJointInterface</hardwareInterface>
      <mechanicalReduction>1</mechanicalReduction>
    </actuator>
  </transmission>
  <transmission name="joint5_trans">
    <type>transmission_interface/SimpleTransmission</type>
    <joint name="joint5">
      <hardwareInterface>PositionJointInterface</hardwareInterface>
    </joint>
    <actuator name="joint5_motor">
      <hardwareInterface>PositionJointInterface</hardwareInterface>
      <mechanicalReduction>1</mechanicalReduction>
    </actuator>
  </transmission>
  <transmission name="joint6_trans">
    <type>transmission_interface/SimpleTransmission</type>
    <joint name="joint6">
      <hardwareInterface>PositionJointInterface</hardwareInterface>
    </joint>
    <actuator name="joint6_motor">
      <hardwareInterface>PositionJointInterface</hardwareInterface>
      <mechanicalReduction>1</mechanicalReduction>
    </actuator>
  </transmission>
  <!-- ========== Gazebo ========== -->
  <gazebo>
    <plugin filename="libgazebo_ros_control.so" name="gazebo_ros_control">
      <robotNamespace>raspigibbon</robotNamespace>
    </plugin>
  </gazebo>
  <gazebo reference="base_link">
    <!-- <selfCollide>true</selfCollide> -->
    <!-- <mu1 value="0.05" /> -->
    <!-- <mu2 value="0.05" /> -->
    <mu1>0.05</mu1>
    <mu2>0.05</mu2>
  </gazebo>
  <gazebo reference="link1">
    <!-- <selfCollide>true</selfCollide> -->
    <!-- <mu1 value="0.05" /> -->
    <!-- <mu2 value="0.05" /> -->
    <mu1>0.05</mu1>
    <mu2>0.05</mu2>
  </gazebo>
  <gazebo reference="link2">
    <!-- <selfCollide>true</selfCollide> -->
    <!-- <mu1 value="0.05" /> -->
    <!-- <mu2 value="0.05" /> -->
    <mu1>0.05</mu1>
    <mu2>0.05</mu2>
  </gazebo>
  <gazebo reference="link3">
    <!-- <selfCollide>true</selfCollide> -->
    <!-- <mu1 value="0.05" /> -->
    <!-- <mu2 value="0.05" /> -->
    <mu1>0.05</mu1>
    <mu2>0.05</mu2>
  </gazebo>
  <gazebo reference="link4">
    <!-- <selfCollide>true</selfCollide> -->
    <!-- <mu1 value="0.05" /> -->
    <!-- <mu2 value="0.05" /> -->
    <mu1>0.05</mu1>
    <mu2>0.05</mu2>
  </gazebo>
  <gazebo reference="link5">
    <!-- <selfCollide>true</selfCollide> -->
    <!-- <mu1 value="0.05" /> -->
    <!-- <mu2 value="0.05" /> -->
    <mu1>0.05</mu1>
    <mu2>0.05</mu2>
  </gazebo>
</robot>

